{
  size: [7, 6, 9],
  entities: [{
    nbt: {
      HurtByTimestamp: 0,
      Riches: 15,
      FallFlying: 0b,
      ForcedAge: 0,
      Invulnerable: 0b,
      AbsorptionAmount: 0f,
      PortalCooldown: 0,
      FallDistance: 0f,
      DeathTime: 0s,
      Xp: 0,
      HandDropChances: [0.085f, 0.085f],
      PersistenceRequired: 1b,
      id: "minecraft:villager",
      UUID: [I; -1630920815, 245714788, -1593885403, 1511953888],
      Age: 0,
      Motion: [0d, -0.0784000015258789d, 0d],
      Leashed: 0b,
      Health: 20f,
      LeftHanded: 0b,
      Air: 300s,
      Dimension: 0,
      Offers: {
        Recipes: [{
          maxUses: 7,
          uses: 0,
          rewardExp: 1b,
          buy: {
            count: 36,
            id: "minecraft:rotten_flesh"
          },
          sell: {
            count: 1,
            id: "minecraft:emerald"
          }
        }, {
          maxUses: 7,
          uses: 0,
          rewardExp: 1b,
          buy: {
            count: 9,
            id: "minecraft:gold_ingot"
          },
          sell: {
            count: 1,
            id: "minecraft:emerald"
          }
        }]
      },
      OnGround: 1b,
      Rotation: [-4.3276978f, -3.41655f],
      HandItems: [{}, {}],
      ArmorDropChances: [0.085f, 0.085f, 0.085f, 0.085f],
      Pos: [-986.5d, 8d, -1060.5d],
      ArmorItems: [{}, {}, {}, {}],
      Fire: -1s,
      CanPickUpLoot: 1b,
      VillagerData: {
        profession: "minecraft:cleric",
        level: 1,
        type: "minecraft:plains"
      },
      attributes: [{
        id: "generic.max_health",
        base: 20d
      }, {
        id: "generic.knockback_resistance",
        base: 0d
      }, {
        id: "generic.movement_speed",
        base: 0.5d
      }, {
        id: "generic.armor",
        base: 0d
      }, {
        id: "generic.armor_toughness",
        base: 0d
      }, {
        modifiers: [{
          amount: -0.07807250298271795d,
          id: "minecraft:random_spawn_bonus",
          operation: "add_multiplied_base"
        }],
        id: "generic.follow_range",
        base: 48d
      }],
      HurtTime: 0s,
      Inventory: [],
      Willing: 0b
    },
    blockPos: [2, 1, 1],
    pos: [2.5d, 1d, 1.5d]
  }, {
    nbt: {
      HurtByTimestamp: 125,
      FallFlying: 0b,
      Invulnerable: 0b,
      AbsorptionAmount: 0f,
      PortalCooldown: 0,
      FallDistance: 0f,
      DeathTime: 0s,
      Xp: 0,
      HandDropChances: [0.085f, 0.085f],
      PersistenceRequired: 1b,
      id: "minecraft:zombie_villager",
      UUID: [I; 669208369, 1839481473, -1764747872, -1340605115],
      ConversionTime: -1,
      Motion: [0d, -0.0784000015258789d, 0d],
      Leashed: 0b,
      Health: 19.05f,
      LeftHanded: 0b,
      Air: 300s,
      Dimension: 0,
      OnGround: 1b,
      Rotation: [-95.78888f, 0f],
      HandItems: [{}, {}],
      ArmorDropChances: [0.085f, 0.085f, 0.085f, 0.085f],
      CanBreakDoors: 0b,
      Pos: [-984.5d, 8d, -1060.699999988079d],
      ArmorItems: [{}, {}, {}, {}],
      Fire: -1s,
      CanPickUpLoot: 0b,
      VillagerData: {
        profession: "minecraft:cleric",
        level: 1,
        type: "minecraft:plains"
      },
      attributes: [{
        id: "generic.max_health",
        base: 20d
      }, {
        modifiers: [{
          amount: 0.033586338385064834d,
          id: "minecraft:random_spawn_bonus",
          operation: "add_value"
        }],
        id: "generic.knockback_resistance",
        base: 0d
      }, {
        id: "generic.movement_speed",
        base: 0.23000000417232513d
      }, {
        id: "generic.armor",
        base: 2d
      }, {
        id: "generic.armor_toughness",
        base: 0d
      }, {
        modifiers: [{
          amount: -0.013882809459502736d,
          id: "minecraft:random_spawn_bonus",
          operation: "add_multiplied_base"
        }],
        id: "generic.follow_range",
        base: 35d
      }, {
        id: "generic.attack_damage",
        base: 3d
      }, {
        id: "zombie.spawn_reinforcements",
        base: 0.08507647017248195d
      }],
      HurtTime: 0s
    },
    blockPos: [4, 1, 1],
    pos: [4.5d, 1d, 1.300000011920929d]
  }],
  blocks: [{
    pos: [1, 0, 0],
    state: 0
  }, {
    pos: [1, 0, 1],
    state: 0
  }, {
    pos: [1, 0, 2],
    state: 0
  }, {
    pos: [1, 0, 3],
    state: 1
  }, {
    pos: [1, 0, 4],
    state: 2
  }, {
    pos: [1, 0, 5],
    state: 3
  }, {
    pos: [1, 0, 6],
    state: 2
  }, {
    pos: [1, 0, 7],
    state: 3
  }, {
    pos: [2, 0, 0],
    state: 0
  }, {
    pos: [2, 0, 1],
    state: 4
  }, {
    pos: [2, 0, 2],
    state: 2
  }, {
    pos: [2, 0, 3],
    state: 2
  }, {
    pos: [2, 0, 4],
    state: 5
  }, {
    pos: [2, 0, 5],
    state: 2
  }, {
    pos: [2, 0, 6],
    state: 2
  }, {
    pos: [2, 0, 7],
    state: 2
  }, {
    pos: [3, 0, 0],
    state: 0
  }, {
    pos: [3, 0, 1],
    state: 0
  }, {
    pos: [3, 0, 2],
    state: 0
  }, {
    pos: [3, 0, 3],
    state: 3
  }, {
    pos: [3, 0, 4],
    state: 2
  }, {
    pos: [3, 0, 5],
    state: 3
  }, {
    pos: [3, 0, 6],
    state: 2
  }, {
    pos: [3, 0, 7],
    state: 3
  }, {
    pos: [4, 0, 0],
    state: 0
  }, {
    pos: [4, 0, 1],
    state: 4
  }, {
    pos: [4, 0, 2],
    state: 2
  }, {
    pos: [4, 0, 3],
    state: 2
  }, {
    pos: [4, 0, 4],
    state: 2
  }, {
    pos: [4, 0, 5],
    state: 2
  }, {
    pos: [4, 0, 6],
    state: 2
  }, {
    pos: [4, 0, 7],
    state: 2
  }, {
    pos: [5, 0, 0],
    state: 0
  }, {
    pos: [5, 0, 1],
    state: 0
  }, {
    pos: [5, 0, 2],
    state: 0
  }, {
    pos: [5, 0, 3],
    state: 6
  }, {
    pos: [5, 0, 4],
    state: 2
  }, {
    pos: [5, 0, 5],
    state: 3
  }, {
    pos: [5, 0, 6],
    state: 5
  }, {
    pos: [5, 0, 7],
    state: 3
  }, {
    pos: [0, 1, 3],
    state: 7
  }, {
    pos: [0, 1, 4],
    state: 7
  }, {
    pos: [0, 1, 5],
    state: 7
  }, {
    pos: [0, 1, 6],
    state: 7
  }, {
    pos: [0, 1, 7],
    state: 7
  }, {
    pos: [1, 1, 0],
    state: 2
  }, {
    pos: [1, 1, 1],
    state: 2
  }, {
    pos: [1, 1, 2],
    state: 7
  }, {
    pos: [1, 1, 8],
    state: 7
  }, {
    pos: [2, 1, 0],
    state: 2
  }, {
    pos: [2, 1, 8],
    state: 8
  }, {
    pos: [3, 1, 0],
    state: 2
  }, {
    pos: [3, 1, 1],
    state: 2
  }, {
    pos: [3, 1, 2],
    state: 7
  }, {
    pos: [3, 1, 8],
    state: 7
  }, {
    pos: [4, 1, 0],
    state: 2
  }, {
    pos: [4, 1, 8],
    state: 7
  }, {
    pos: [5, 1, 0],
    state: 2
  }, {
    pos: [5, 1, 1],
    state: 2
  }, {
    pos: [5, 1, 2],
    state: 7
  }, {
    pos: [5, 1, 8],
    state: 7
  }, {
    pos: [6, 1, 3],
    state: 7
  }, {
    pos: [6, 1, 4],
    state: 7
  }, {
    pos: [6, 1, 5],
    state: 7
  }, {
    pos: [6, 1, 6],
    state: 7
  }, {
    pos: [6, 1, 7],
    state: 7
  }, {
    pos: [0, 2, 3],
    state: 4
  }, {
    pos: [0, 2, 4],
    state: 2
  }, {
    pos: [0, 2, 5],
    state: 2
  }, {
    pos: [0, 2, 6],
    state: 4
  }, {
    pos: [0, 2, 7],
    state: 2
  }, {
    pos: [1, 2, 0],
    state: 2
  }, {
    pos: [1, 2, 1],
    state: 2
  }, {
    pos: [1, 2, 2],
    state: 2
  }, {
    pos: [1, 2, 8],
    state: 5
  }, {
    pos: [2, 2, 0],
    state: 2
  }, {
    pos: [2, 2, 8],
    state: 2
  }, {
    pos: [3, 2, 0],
    state: 2
  }, {
    pos: [3, 2, 1],
    state: 2
  }, {
    pos: [3, 2, 2],
    state: 4
  }, {
    pos: [3, 2, 8],
    state: 4
  }, {
    pos: [4, 2, 0],
    state: 2
  }, {
    pos: [4, 2, 8],
    state: 2
  }, {
    pos: [5, 2, 0],
    state: 2
  }, {
    pos: [5, 2, 1],
    state: 2
  }, {
    pos: [5, 2, 2],
    state: 2
  }, {
    pos: [5, 2, 8],
    state: 4
  }, {
    pos: [6, 2, 3],
    state: 2
  }, {
    pos: [6, 2, 4],
    state: 2
  }, {
    pos: [6, 2, 5],
    state: 4
  }, {
    pos: [6, 2, 6],
    state: 5
  }, {
    pos: [6, 2, 7],
    state: 2
  }, {
    pos: [0, 3, 3],
    state: 2
  }, {
    pos: [0, 3, 4],
    state: 5
  }, {
    pos: [0, 3, 5],
    state: 2
  }, {
    pos: [0, 3, 6],
    state: 2
  }, {
    pos: [0, 3, 7],
    state: 2
  }, {
    pos: [1, 3, 0],
    state: 2
  }, {
    pos: [1, 3, 1],
    state: 2
  }, {
    pos: [1, 3, 2],
    state: 2
  }, {
    pos: [1, 3, 8],
    state: 2
  }, {
    pos: [2, 3, 0],
    state: 2
  }, {
    pos: [2, 3, 2],
    state: 2
  }, {
    pos: [2, 3, 8],
    state: 2
  }, {
    pos: [3, 3, 0],
    state: 2
  }, {
    pos: [3, 3, 1],
    state: 2
  }, {
    pos: [3, 3, 2],
    state: 2
  }, {
    pos: [3, 3, 8],
    state: 2
  }, {
    pos: [4, 3, 0],
    state: 2
  }, {
    pos: [4, 3, 2],
    state: 2
  }, {
    pos: [4, 3, 8],
    state: 2
  }, {
    pos: [5, 3, 0],
    state: 2
  }, {
    pos: [5, 3, 1],
    state: 2
  }, {
    pos: [5, 3, 2],
    state: 2
  }, {
    pos: [5, 3, 8],
    state: 2
  }, {
    pos: [6, 3, 3],
    state: 2
  }, {
    pos: [6, 3, 4],
    state: 2
  }, {
    pos: [6, 3, 5],
    state: 2
  }, {
    pos: [6, 3, 6],
    state: 2
  }, {
    pos: [6, 3, 7],
    state: 2
  }, {
    pos: [1, 4, 3],
    state: 2
  }, {
    pos: [1, 4, 4],
    state: 2
  }, {
    pos: [1, 4, 5],
    state: 2
  }, {
    pos: [1, 4, 6],
    state: 2
  }, {
    pos: [1, 4, 7],
    state: 2
  }, {
    pos: [2, 4, 1],
    state: 2
  }, {
    pos: [2, 4, 2],
    state: 2
  }, {
    pos: [2, 4, 3],
    state: 2
  }, {
    pos: [2, 4, 4],
    state: 2
  }, {
    pos: [2, 4, 5],
    state: 2
  }, {
    pos: [2, 4, 6],
    state: 5
  }, {
    pos: [2, 4, 7],
    state: 2
  }, {
    pos: [2, 4, 8],
    state: 2
  }, {
    pos: [3, 4, 1],
    state: 2
  }, {
    pos: [3, 4, 2],
    state: 2
  }, {
    pos: [3, 4, 3],
    state: 2
  }, {
    pos: [3, 4, 4],
    state: 2
  }, {
    pos: [3, 4, 5],
    state: 6
  }, {
    pos: [3, 4, 6],
    state: 2
  }, {
    pos: [3, 4, 8],
    state: 2
  }, {
    pos: [4, 4, 1],
    state: 2
  }, {
    pos: [4, 4, 2],
    state: 2
  }, {
    pos: [4, 4, 3],
    state: 2
  }, {
    pos: [4, 4, 4],
    state: 2
  }, {
    pos: [4, 4, 5],
    state: 2
  }, {
    pos: [4, 4, 6],
    state: 2
  }, {
    pos: [4, 4, 7],
    state: 2
  }, {
    pos: [4, 4, 8],
    state: 2
  }, {
    pos: [5, 4, 3],
    state: 2
  }, {
    pos: [5, 4, 4],
    state: 2
  }, {
    pos: [5, 4, 5],
    state: 2
  }, {
    pos: [5, 4, 6],
    state: 2
  }, {
    pos: [5, 4, 7],
    state: 2
  }, {
    pos: [2, 5, 7],
    state: 2
  }, {
    pos: [3, 5, 6],
    state: 2
  }, {
    pos: [3, 5, 8],
    state: 2
  }, {
    pos: [4, 5, 7],
    state: 2
  }, {
    pos: [1, 1, 3],
    state: 9
  }, {
    pos: [1, 1, 4],
    state: 9
  }, {
    pos: [1, 1, 5],
    state: 10
  }, {
    pos: [1, 1, 7],
    state: 10
  }, {
    pos: [2, 1, 1],
    state: 10
  }, {
    pos: [2, 1, 2],
    state: 11
  }, {
    pos: [2, 1, 3],
    state: 10
  }, {
    pos: [2, 1, 4],
    state: 10
  }, {
    pos: [2, 1, 5],
    state: 10
  }, {
    pos: [2, 1, 6],
    state: 10
  }, {
    pos: [2, 1, 7],
    state: 10
  }, {
    pos: [3, 1, 3],
    state: 10
  }, {
    pos: [3, 1, 4],
    state: 10
  }, {
    pos: [3, 1, 5],
    state: 10
  }, {
    pos: [3, 1, 6],
    state: 10
  }, {
    pos: [3, 1, 7],
    state: 10
  }, {
    pos: [4, 1, 1],
    state: 10
  }, {
    pos: [4, 1, 2],
    state: 11
  }, {
    pos: [4, 1, 3],
    state: 10
  }, {
    pos: [4, 1, 4],
    state: 10
  }, {
    pos: [4, 1, 5],
    state: 10
  }, {
    pos: [4, 1, 6],
    state: 10
  }, {
    pos: [4, 1, 7],
    state: 10
  }, {
    pos: [5, 1, 3],
    state: 10
  }, {
    pos: [5, 1, 4],
    state: 12
  }, {
    pos: [5, 1, 5],
    state: 13
  }, {
    pos: [5, 1, 6],
    state: 14
  }, {
    pos: [5, 1, 7],
    state: 15
  }, {
    pos: [1, 2, 3],
    state: 10
  }, {
    pos: [1, 2, 4],
    state: 10
  }, {
    pos: [1, 2, 5],
    state: 10
  }, {
    pos: [1, 2, 7],
    state: 10
  }, {
    pos: [2, 2, 1],
    state: 10
  }, {
    pos: [2, 2, 2],
    state: 11
  }, {
    pos: [2, 2, 3],
    state: 10
  }, {
    pos: [2, 2, 4],
    state: 10
  }, {
    pos: [2, 2, 5],
    state: 10
  }, {
    pos: [2, 2, 6],
    state: 10
  }, {
    pos: [2, 2, 7],
    state: 10
  }, {
    pos: [3, 2, 4],
    state: 10
  }, {
    pos: [3, 2, 5],
    state: 10
  }, {
    pos: [3, 2, 6],
    state: 10
  }, {
    pos: [3, 2, 7],
    state: 16
  }, {
    pos: [4, 2, 1],
    state: 10
  }, {
    pos: [4, 2, 2],
    state: 11
  }, {
    pos: [4, 2, 3],
    state: 10
  }, {
    pos: [4, 2, 4],
    state: 10
  }, {
    pos: [4, 2, 5],
    state: 10
  }, {
    pos: [4, 2, 6],
    state: 10
  }, {
    pos: [4, 2, 7],
    state: 10
  }, {
    pos: [5, 2, 3],
    state: 10
  }, {
    pos: [5, 2, 4],
    state: 10
  }, {
    pos: [5, 2, 5],
    state: 10
  }, {
    pos: [5, 2, 7],
    state: 17
  }, {
    pos: [1, 3, 3],
    state: 18
  }, {
    pos: [1, 3, 4],
    state: 10
  }, {
    pos: [1, 3, 5],
    state: 10
  }, {
    pos: [1, 3, 6],
    state: 10
  }, {
    pos: [1, 3, 7],
    state: 10
  }, {
    pos: [2, 3, 1],
    state: 10
  }, {
    pos: [2, 3, 3],
    state: 10
  }, {
    pos: [2, 3, 4],
    state: 10
  }, {
    pos: [2, 3, 5],
    state: 10
  }, {
    pos: [2, 3, 6],
    state: 10
  }, {
    pos: [2, 3, 7],
    state: 19
  }, {
    pos: [3, 3, 3],
    state: 20
  }, {
    pos: [3, 3, 4],
    state: 10
  }, {
    pos: [3, 3, 5],
    state: 10
  }, {
    pos: [3, 3, 6],
    state: 10
  }, {
    pos: [3, 3, 7],
    state: 16
  }, {
    pos: [4, 3, 1],
    state: 10
  }, {
    pos: [4, 3, 3],
    state: 10
  }, {
    pos: [4, 3, 4],
    state: 10
  }, {
    pos: [4, 3, 5],
    state: 10
  }, {
    pos: [4, 3, 6],
    state: 10
  }, {
    pos: [4, 3, 7],
    state: 19
  }, {
    pos: [5, 3, 3],
    state: 10
  }, {
    pos: [5, 3, 4],
    state: 10
  }, {
    pos: [5, 3, 5],
    state: 10
  }, {
    pos: [5, 3, 6],
    state: 10
  }, {
    pos: [5, 3, 7],
    state: 10
  }, {
    pos: [3, 4, 7],
    state: 16
  }, {
    pos: [3, 5, 7],
    state: 16
  }, {
    nbt: {
      Items: [],
      id: "minecraft:chest"
    },
    pos: [1, 1, 6],
    state: 21
  }, {
    nbt: {
      metadata: "chest",
      mirror: "NONE",
      ignoreEntities: 0b,
      powered: 0b,
      seed: 0l,
      author: "Searge",
      rotation: "NONE",
      mode: "DATA",
      posX: 1,
      posY: 1,
      sizeX: 0,
      integrity: 1f,
      posZ: 1,
      showair: 0b,
      name: "",
      id: "minecraft:structure_block",
      sizeY: 0,
      showboundingbox: 0b,
      sizeZ: 0
    },
    pos: [1, 2, 6],
    state: 22
  }, {
    nbt: {
      front_text: {
        filtered_messages: ["{"text":""}", "{"text":"<----"}", "{"text":"---->"}", "{"text":""}"],
        has_glowing_text: 0b,
        color: "black",
        messages: ["{"text":""}", "{"text":"<----"}", "{"text":"---->"}", "{"text":""}"]
      },
      back_text: {
        has_glowing_text: 0b,
        color: "black",
        messages: ["{"text":""}", "{"text":""}", "{"text":""}", "{"text":""}"]
      },
      id: "minecraft:sign"
    },
    pos: [3, 2, 3],
    state: 23
  }, {
    nbt: {
      Items: [{
        count: 1,
        Slot: 1b,
        components: {
          minecraft:potion_contents: {
            potion: "minecraft:weakness"
          }
        },
        id: "minecraft:splash_potion"
      }],
      id: "minecraft:brewing_stand",
      BrewTime: 0s,
      Fuel: 0b
    },
    pos: [5, 2, 6],
    state: 24
  }],
  palette: [{
    Name: "minecraft:stone"
  }, {
    Name: "minecraft:polished_andesite"
  }, {
    Name: "minecraft:stone_bricks"
  }, {
    Name: "minecraft:chiseled_stone_bricks"
  }, {
    Name: "minecraft:cracked_stone_bricks"
  }, {
    Name: "minecraft:infested_stone_bricks"
  }, {
    Name: "minecraft:infested_chiseled_stone_bricks"
  }, {
    Name: "minecraft:mossy_stone_bricks"
  }, {
    Name: "minecraft:infested_mossy_stone_bricks"
  }, {
    Name: "minecraft:red_carpet"
  }, {
    Name: "minecraft:air"
  }, {
    Properties: {
      east: "true",
      waterlogged: "false",
      south: "false",
      north: "false",
      west: "true"
    },
    Name: "minecraft:iron_bars"
  }, {
    Properties: {
      level: "2"
    },
    Name: "minecraft:water_cauldron"
  }, {
    Properties: {
      half: "top",
      waterlogged: "false",
      shape: "straight",
      facing: "north"
    },
    Name: "minecraft:spruce_stairs"
  }, {
    Properties: {
      waterlogged: "false",
      type: "top"
    },
    Name: "minecraft:spruce_slab"
  }, {
    Properties: {
      half: "top",
      waterlogged: "false",
      shape: "straight",
      facing: "south"
    },
    Name: "minecraft:spruce_stairs"
  }, {
    Properties: {
      waterlogged: "false",
      facing: "north"
    },
    Name: "minecraft:ladder"
  }, {
    Name: "minecraft:potted_cactus"
  }, {
    Name: "minecraft:cobweb"
  }, {
    Properties: {
      facing: "north"
    },
    Name: "minecraft:wall_torch"
  }, {
    Properties: {
      facing: "south"
    },
    Name: "minecraft:wall_torch"
  }, {
    Properties: {
      waterlogged: "false",
      facing: "east",
      type: "single"
    },
    Name: "minecraft:chest"
  }, {
    Properties: {
      mode: "data"
    },
    Name: "minecraft:structure_block"
  }, {
    Properties: {
      waterlogged: "false",
      facing: "south"
    },
    Name: "minecraft:oak_wall_sign"
  }, {
    Properties: {
      has_bottle_0: "false",
      has_bottle_1: "true",
      has_bottle_2: "false"
    },
    Name: "minecraft:brewing_stand"
  }],
  DataVersion: 3955
}
